<?xml version="1.0"?>
<!-- 
  URDF for Unitree G1 with added Gazebo sensor plugins.
  This model builds upon the basic structure from Chapter 6.
-->
<robot name="unitree_g1_sensors">

  <!-- Main Body -->
  <link name="base_link">
    <visual>
      <geometry>
        <box size="0.2 0.15 0.3"/>
      </geometry>
      <material name="white">
        <color rgba="1 1 1 1"/>
      </material>
    </visual>
    <collision>
      <geometry>
        <box size="0.2 0.15 0.3"/>
      </geometry>
    </collision>
    <inertial>
      <origin xyz="0 0 0" rpy="0 0 0"/>
      <mass value="5.0"/>
      <inertia ixx="0.1" ixy="0.0" ixz="0.0" iyy="0.1" iyz="0.0" izz="0.05"/>
    </inertial>
  </link>
  
  <!-- Head Link for Camera -->
  <link name="head_link">
    <visual>
      <geometry>
        <box size="0.1 0.1 0.1"/>
      </geometry>
      <material name="white"/>
    </visual>
    <collision>
      <geometry>
        <box size="0.1 0.1 0.1"/>
      </geometry>
    </collision>
    <inertial>
      <mass value="0.5"/>
      <inertia ixx="0.001" ixy="0" ixz="0" iyy="0.001" izz="0.001"/>
    </inertial>
  </link>

  <joint name="torso_to_head_joint" type="fixed">
    <parent link="base_link"/>
    <child link="head_link"/>
    <origin xyz="0 0 0.2" rpy="0 0 0"/>
  </joint>

  <!-- Placeholder for a simple leg -->
  <link name="thigh_link">
    <visual>
      <geometry>
        <cylinder radius="0.03" length="0.2"/>
      </geometry>
      <origin xyz="0 0 -0.1" rpy="0 0 0"/>
      <material name="black">
        <color rgba="0.1 0.1 0.1 1"/>
      </material>
    </visual>
    <collision>
      <geometry>
        <cylinder radius="0.03" length="0.2"/>
      </geometry>
      <origin xyz="0 0 -0.1" rpy="0 0 0"/>
    </collision>
    <inertial>
      <origin xyz="0 0 -0.1" rpy="0 0 0"/>
      <mass value="1.0"/>
      <inertia ixx="0.01" ixy="0.0" ixz="0.0" iyy="0.01" iyz="0.0" izz="0.005"/>
    </inertial>
  </link>

  <joint name="base_to_thigh_joint" type="revolute">
    <parent link="base_link"/>
    <child link="thigh_link"/>
    <origin xyz="-0.05 0 -0.15" rpy="0 0 0"/>
    <axis xyz="1 0 0"/>
    <limit lower="-0.5" upper="0.5" effort="10.0" velocity="1.0"/>
  </joint>

  <material name="white"/>
  <material name="black"/>

  <!-- GAZEBO SENSOR PLUGINS -->

  <!-- 1. Head Camera Sensor -->
  <gazebo reference="head_link">
    <sensor type="camera" name="head_camera">
      <update_rate>30.0</update_rate>
      <camera name="head">
        <horizontal_fov>1.396</horizontal_fov>
        <image>
          <width>800</width>
          <height>800</height>
          <format>R8G8B8</format>
        </image>
        <clip>
          <near>0.02</near>
          <far>300</far>
        </clip>
      </camera>
      <plugin name="camera_controller" filename="libgazebo_ros_camera.so">
        <ros>
          <namespace>/robot</namespace>
          <argument>--ros-args -r image_raw:=image_raw</argument>
          <argument>--ros-args -r camera_info:=camera_info</argument>
        </ros>
        <camera_name>head_camera</camera_name>
        <frame_name>head_camera_link</frame_name>
      </plugin>
    </sensor>
  </gazebo>

  <!-- 2. Base LiDAR Sensor -->
  <gazebo reference="base_link">
    <sensor type="ray" name="lidar_sensor">
      <pose>0 0 0.1 0 0 0</pose>
      <visualize>true</visualize>
      <update_rate>10</update_rate>
      <ray>
        <scan>
          <horizontal>
            <samples>720</samples>
            <resolution>1</resolution>
            <min_angle>-1.57</min_angle>
            <max_angle>1.57</max_angle>
          </horizontal>
        </scan>
        <range>
          <min>0.10</min>
          <max>30.0</max>
          <resolution>0.01</resolution>
        </range>
      </ray>
      <plugin name="gazebo_ros_head_hokuyo_controller" filename="libgazebo_ros_ray_sensor.so">
        <ros>
          <namespace>/robot</namespace>
          <argument>--ros-args -r out:=scan</argument>
        </ros>
        <output_type>sensor_msgs/LaserScan</output_type>
        <frame_name>lidar_link</frame_name>
      </plugin>
    </sensor>
  </gazebo>

  <!-- 3. Base IMU Sensor -->
  <gazebo reference="base_link">
    <sensor name="imu_sensor" type="imu">
      <always_on>true</always_on>
      <update_rate>100</update_rate>
      <plugin filename="libgazebo_ros_imu_sensor.so" name="imu_plugin">
        <ros>
            <namespace>/robot</namespace>
            <remapping>~/out:=imu/data</remapping>
        </ros>
      </plugin>
    </sensor>
  </gazebo>

</robot>
